Workbook

Sheet Dashboard
B2: MI SISTEMA MCL 2:1
B3: Resultados desde el 14/08/2026 · se actualiza solo al añadir operaciones en la pestaña CARGAR OPERACIONES
B6: CAPITAL ACTUAL | D6: BENEFICIO NETO | F6: % DE ACIERTO | H6: PROFIT FACTOR | J6: ESPERANZA / OP. | L6: DRAWDOWN ACTUAL | N6: BLOQUE EN CURSO
B7: =O31 -> 8748.36 | D7: =E23 -> 163.84 | F7: =E21 -> 0.375 | H7: =E26 -> 1.103153 | J7: =J21 -> 10.24 | L7: =O36 -> -680.96 | N7: =O39&" / "&Parametros!$C$10 -> 16 / 20
B8: ="Inicial "&TEXT(O30,"$#,##0") -> Inicial $8,585 | D8: =TEXT(O32,"+0.0%;-0.0%")&" sobre el capital" -> +1.9% sobre el capital | F8: ="Mínimo necesario "&TEXT(E22,"0.0%") -> Mínimo necesario 35.2% | H8: ="Meta por bloque "&TEXT(Parametros!$C$11,"0.00") -> Meta por bloque 1.30 | J8: =TEXT(J22,"+0.00;-0.00")&" R por operación" -> +0.07 R por operación | L8: ="Máximo "&TEXT(O34,"$#,##0;-$#,##0") -> Máximo -$681 | N8: ="Bloque "&O38&" · faltan "&(Parametros!$C$10-O39)&" ops" -> Bloque 1 · faltan 4 ops
B10: ="Progreso del bloque "&O38 -> Progreso del bloque 1 | D10: =O39/Parametros!$C$10 -> 0.8 | N10: =TEXT(SUMIFS('CARGAR OPERACIONES'!$S$7:$S$506,'CARGAR OPERACIONES'!$O$7:$O$506,O38),"+$#,##0;-$#,##0")&" en el bloque" -> +$164 en el bloque
B12: =IF(E18=0,"Registra tu primera operación y empieza a construir tu estadística.",IF(O20<=-3,"★ Racha de "&-O20&" pérdidas: es estadística, no un error. Con un 2:1 una sola ganadora recupera casi dos stops. Ejecuta el plan, sin improvisar.",IF(E26>=Parametros!$C$11,"★ El sistema está rindiendo por encima de la meta (PF "&TEXT(E26,"0.00")&"). Mantén la disciplina: no cambies lo que funciona.",IF(E26>=1,"★ Sistema en positivo (PF "&TEXT(E26,"0.00")&"). Paciencia: cada operación disciplinada suma a la ventaja.","★ Fase exigente: revisa la ejecución, no el sistema. ¿Cumple cada entrada el patrón al 100%? Disciplina actual: "&TEXT(J25,"0%")&".")))) -> ★ Racha de 4 pérdidas: es estadística, no un error. Con un 2:1 una sola ganadora recupera casi dos stops. Ejecuta el plan, sin improvisar.
B15: ✏ ¿Nueva operación? Haz clic aquí para ir a la pestaña CARGAR OPERACIONES →
B17: RESULTADO | G17: POR OPERACIÓN | L17: RACHAS Y ÚLTIMAS 10
B18: Operaciones | E18: =COUNT('CARGAR OPERACIONES'!$S$7:$S$506) -> 16 | G18: Ganancia media | J18: =IF(E19=0,0,E24/E19) -> 292.02667 | L18: Máx. racha ganadora | O18: =MAX(0,'CARGAR OPERACIONES'!$Z$7:$Z$506) -> 2
B19: Ganadoras | E19: =COUNTIF('CARGAR OPERACIONES'!$S$7:$S$506,">0") -> 6 | G19: Pérdida media | J19: =IF(E20=0,0,E25/E20) -> -158.832 | L19: Máx. racha perdedora | O19: =-MIN(0,'CARGAR OPERACIONES'!$Z$7:$Z$506) -> 4
B20: Perdedoras | E20: =COUNTIF('CARGAR OPERACIONES'!$S$7:$S$506,"<=0") -> 10 | G20: Ratio ganancia / pérdida | J20: =IFERROR(J18/-J19,0) -> 1.8385884 | L20: Racha actual | O20: =IF(E18=0,0,INDEX('CARGAR OPERACIONES'!$Z$7:$Z$506,E18)) -> -4
B21: % de acierto | E21: =IF(E18=0,0,E19/E18) -> 0.375 | G21: Esperanza por operación | J21: =IF(E18=0,0,E23/E18) -> 10.24 | L21: Operaciones en la muestra | O21: =MIN(10,E18) -> 10
B22: % de acierto mínimo (break-even) | E22: =IFERROR(-J19/(J18-J19),0) -> 0.35228778 | G22: Esperanza en R | J22: =IFERROR(AVERAGE('CARGAR OPERACIONES'!$U$7:$U$506),0) -> 0.068266667 | L22: % acierto últimas 10 | O22: =IF(O21=0,0,COUNTIFS('CARGAR OPERACIONES'!$A$7:$A$506,">"&(E18-10),'CARGAR OPERACIONES'!$S$7:$S$506,">0")/O21) -> 0.2
B23: Beneficio neto | E23: =SUM('CARGAR OPERACIONES'!$S$7:$S$506) -> 163.84 | G23: Duración media ganadoras (min) | J23: =IFERROR(AVERAGEIF('CARGAR OPERACIONES'!$S$7:$S$506,">0",'CARGAR OPERACIONES'!$P$7:$P$506),"-") -> 91 | L23: Neto últimas 10 | O23: =SUMIFS('CARGAR OPERACIONES'!$S$7:$S$506,'CARGAR OPERACIONES'!$A$7:$A$506,">"&(E18-10)) -> -680.96
B24: Beneficio bruto (ganadoras) | E24: =SUMIF('CARGAR OPERACIONES'!$S$7:$S$506,">0") -> 1752.16 | G24: Duración media perdedoras (min) | J24: =IFERROR(AVERAGEIF('CARGAR OPERACIONES'!$S$7:$S$506,"<=0",'CARGAR OPERACIONES'!$P$7:$P$506),"-") -> 19.9 | L24: Profit factor últimas 10 | O24: =IFERROR(SUMIFS('CARGAR OPERACIONES'!$S$7:$S$506,'CARGAR OPERACIONES'!$A$7:$A$506,">"&(E18-10),'CARGAR OPERACIONES'!$S$7:$S$506,">0")/-SUMIFS('CARGAR OPERACIONES'!$S$7:$S$506,'CARGAR OPERACIONES'!$A$7:$A$506,">"&(E18-10),'CARGAR OPERACIONES'!$S$7:$S$506,"<=0"),0) -> 0.46377725
B25: Pérdida bruta (perdedoras) | E25: =SUMIF('CARGAR OPERACIONES'!$S$7:$S$506,"<=0") -> -1588.32 | G25: % operaciones disciplinadas | J25: =IF(E18=0,0,COUNTIF('CARGAR OPERACIONES'!$L$7:$L$506,"SI")/E18) -> 0.9375
B26: Profit factor | E26: =IF(E25=0,0,E24/-E25) -> 1.103153 | G26: Neto de operaciones indisciplinadas | J26: =SUMIF('CARGAR OPERACIONES'!$L$7:$L$506,"NO",'CARGAR OPERACIONES'!$S$7:$S$506) -> -159.2
B27: Comisiones pagadas | E27: =SUM('CARGAR OPERACIONES'!$R$7:$R$506) -> 136.16
L29: CAPITAL Y RIESGO
B30: CURVA DE CAPITAL | L30: Capital inicial | O30: =Parametros!$C$6 -> 8584.52
L31: Capital actual | O31: =O30+E23 -> 8748.36
L32: Rentabilidad del periodo | O32: =IFERROR(E23/O30,0) -> 0.019085517
L33: Capital máximo alcanzado | O33: =MAX(Parametros!$C$6,'CARGAR OPERACIONES'!$V$7:$V$506) -> 9429.32
L34: Máximo drawdown $ | O34: =MIN(0,'CARGAR OPERACIONES'!$X$7:$X$506) -> -680.96
L35: Máximo drawdown % | O35: =MIN(0,'CARGAR OPERACIONES'!$Y$7:$Y$506) -> -0.072217297
L36: Drawdown actual $ | O36: =O31-O33 -> -680.96
L37: Factor de recuperación | O37: =IF(O34=0,0,E23/-O34) -> 0.2406015
L38: Bloque en curso | O38: =IF(E18=0,1,INDEX('CARGAR OPERACIONES'!$O$7:$O$506,E18)) -> 1
L39: Operaciones del bloque en curso | O39: =COUNTIF('CARGAR OPERACIONES'!$O$7:$O$506,O38) -> 16

Sheet CARGAR OPERACIONES
B2: ✏ CARGAR OPERACIONES — aquí anotas cada trade | P2: CÓMO CARGAR: 1) Ve a la primera fila vacía. 2) Completa las columnas color crema B→N (fecha, horas, símbolo, C/L, contratos, patrón, ticks totales, MFE, MAE, SI/NO, motivo, notas). 3) No toques las columnas azules: se calculan solas.
B3: Esta es la ÚNICA pestaña donde escribes. Todo lo demás (Dashboard, Bloques, Semanas, Análisis) se actualiza solo.
B5: ▼ COMPLETA ESTAS COLUMNAS ▼ | O5: CÁLCULOS AUTOMÁTICOS (no escribir)
A6: Nº | B6: Fecha | C6: Hora entrada | D6: Hora salida | E6: Símbolo | F6: C / L | G6: Contratos | H6: Patrón | I6: Ticks (total) | J6: MFE (ticks/contrato) | K6: MAE (ticks/contrato) | L6: Disciplinada | M6: Motivo indisciplina | N6: Imagen / notas | O6: Bloque | P6: Duración (min) | Q6: Bruto $ | R6: Comisión $ | S6: Neto $ | T6: Resultado | U6: Múltiplo R | V6: Capital $ | W6: Pico capital $ | X6: Drawdown $ | Y6: Drawdown % | Z6: Racha | AA6: Semana (lunes) | AB6: Mes | AC6: Día | AD6: Hora | AE6: Pico bloque $ | AF6: DD bloque $ | AG6: Racha bloque
A7: =IF(B7="","",ROW()-6) -> 1 | B7: 46248 | C7: 0.47291667 | D7: 0.5625 | E7: MCL | F7: L | G7: 5 | H7: Giro+VC | I7: 300 | J7: 60 | K7: 6 | L7: SI | O7: =IF($B7="","",INT((A7-1)/Parametros!$C$10)+1) -> 1 | P7: =IF($B7="","",IF(OR(C7="",D7=""),"",ROUND((D7-C7)*1440,0))) -> 129 | Q7: =IF($B7="","",I7*VLOOKUP(E7,Parametros!$B$18:$D$24,2,FALSE())) -> 300 | R7: =IF($B7="","",G7*VLOOKUP(E7,Parametros!$B$18:$D$24,3,FALSE())) -> 9.2 | S7: =IF($B7="","",Q7-R7) -> 290.8 | T7: =IF($B7="","",IF(S7>0,"G","P")) -> G | U7: =IF($B7="","",S7/Parametros!$C$8) -> 1.9386667 | V7: =IF($B7="","",Parametros!$C$6+SUM($S$7:S7)) -> 8875.32 | W7: =IF($B7="","",MAX(V7,Parametros!$C$6)) -> 8875.32 | X7: =IF($B7="","",V7-W7) -> 0 | Y7: =IF($B7="","",X7/W7) -> 0 | Z7: =IF($B7="","",IF(T7="G",IF(N(Z6)>0,Z6+1,1),IF(N(Z6)<0,Z6-1,-1))) -> 1 | AA7: =IF($B7="","",B7-WEEKDAY(B7,2)+1) -> 46244 | AB7: =IF($B7="","",DATE(YEAR(B7),MONTH(B7),1)) -> 46235 | AC7: =IF($B7="","",CHOOSE(WEEKDAY(B7,2),"Lunes","Martes","Miércoles","Jueves","Viernes","Sábado","Domingo")) -> Viernes | AD7: =IF($B7="","",HOUR(C7)) -> 11 | AE7: =IF($B7="","",IF(O7<>O6,MAX(V7-S7,V7),MAX(V7,AE6))) -> 8875.32 | AF7: =IF($B7="","",V7-AE7) -> 0 | AG7: =IF($B7="","",IF(O7<>O6,IF(T7="G",1,-1),IF(T7="G",IF(N(AG6)>0,AG6+1,1),IF(N(AG6)<0,AG6-1,-1)))) -> 1
A8: =IF(B8="","",ROW()-6) -> 2 | B8: 46253 | C8: 0.47708333 | D8: 0.51388889 | E8: MCL | F8: L | G8: 5 | H8: ESTRUC+VC | I8: 300 | J8: 60 | K8: 21 | L8: SI | O8: =IF($B8="","",INT((A8-1)/Parametros!$C$10)+1) -> 1 | P8: =IF($B8="","",IF(OR(C8="",D8=""),"",ROUND((D8-C8)*1440,0))) -> 53 | Q8: =IF($B8="","",I8*VLOOKUP(E8,Parametros!$B$18:$D$24,2,FALSE())) -> 300 | R8: =IF($B8="","",G8*VLOOKUP(E8,Parametros!$B$18:$D$24,3,FALSE())) -> 9.2 | S8: =IF($B8="","",Q8-R8) -> 290.8 | T8: =IF($B8="","",IF(S8>0,"G","P")) -> G | U8: =IF($B8="","",S8/Parametros!$C$8) -> 1.9386667 | V8: =IF($B8="","",Parametros!$C$6+SUM($S$7:S8)) -> 9166.12 | W8: =IF($B8="","",MAX(V8,W7)) -> 9166.12 | X8: =IF($B8="","",V8-W8) -> 0 | Y8: =IF($B8="","",X8/W8) -> 0 | Z8: =IF($B8="","",IF(T8="G",IF(N(Z7)>0,Z7+1,1),IF(N(Z7)<0,Z7-1,-1))) -> 2 | AA8: =IF($B8="","",B8-WEEKDAY(B8,2)+1) -> 46251 | AB8: =IF($B8="","",DATE(YEAR(B8),MONTH(B8),1)) -> 46235 | AC8: =IF($B8="","",CHOOSE(WEEKDAY(B8,2),"Lunes","Martes","Miércoles","Jueves","Viernes","Sábado","Domingo")) -> Miércoles | AD8: =IF($B8="","",HOUR(C8)) -> 11 | AE8: =IF($B8="","",IF(O8<>O7,MAX(V8-S8,V8),MAX(V8,AE7))) -> 9166.12 | AF8: =IF($B8="","",V8-AE8) -> 0 | AG8: =IF($B8="","",IF(O8<>O7,IF(T8="G",1,-1),IF(T8="G",IF(N(AG7)>0,AG7+1,1),IF(N(AG7)<0,AG7-1,-1)))) -> 2
A9: =IF(B9="","",ROW()-6) -> 3 | B9: 46254 | C9: 0.49791667 | D9: 0.50347222 | E9: MCL | F9: C | G9: 5 | H9: ESTRUC+VC | I9: -150 | J9: 12 | K9: 30 | L9: SI | O9: =IF($B9="","",INT((A9-1)/Parametros!$C$10)+1) -> 1 | P9: =IF($B9="","",IF(OR(C9="",D9=""),"",ROUND((D9-C9)*1440,0))) -> 8 | Q9: =IF($B9="","",I9*VLOOKUP(E9,Parametros!$B$18:$D$24,2,FALSE())) -> -150 | R9: =IF($B9="","",G9*VLOOKUP(E9,Parametros!$B$18:$D$24,3,FALSE())) -> 9.2 | S9: =IF($B9="","",Q9-R9) -> -159.2 | T9: =IF($B9="","",IF(S9>0,"G","P")) -> P | U9: =IF($B9="","",S9/Parametros!$C$8) -> -1.0613333 | V9: =IF($B9="","",Parametros!$C$6+SUM($S$7:S9)) -> 9006.92 | W9: =IF($B9="","",MAX(V9,W8)) -> 9166.12 | X9: =IF($B9="","",V9-W9) -> -159.2 | Y9: =IF($B9="","",X9/W9) -> -0.017368309 | Z9: =IF($B9="","",IF(T9="G",IF(N(Z8)>0,Z8+1,1),IF(N(Z8)<0,Z8-1,-1))) -> -1 | AA9: =IF($B9="","",B9-WEEKDAY(B9,2)+1) -> 46251 | AB9: =IF($B9="","",DATE(YEAR(B9),MONTH(B9),1)) -> 46235 | AC9: =IF($B9="","",CHOOSE(WEEKDAY(B9,2),"Lunes","Martes","Miércoles","Jueves","Viernes","Sábado","Domingo")) -> Jueves | AD9: =IF($B9="","",HOUR(C9)) -> 11 | AE9: =IF($B9="","",IF(O9<>O8,MAX(V9-S9,V9),MAX(V9,AE8))) -> 9166.12 | AF9: =IF($B9="","",V9-AE9) -> -159.2 | AG9: =IF($B9="","",IF(O9<>O8,IF(T9="G",1,-1),IF(T9="G",IF(N(AG8)>0,AG8+1,1),IF(N(AG8)<0,AG8-1,-1)))) -> -1
A10: =IF(B10="","",ROW()-6) -> 4 | B10: 46260 | C10: 0.47152778 | D10: 0.50694444 | E10: MCL | F10: L | G10: 5 | H10: ESTRUC+VC | I10: 300 | J10: 60 | K10: 9 | L10: SI | O10: =IF($B10="","",INT((A10-1)/Parametros!$C$10)+1) -> 1 | P10: =IF($B10="","",IF(OR(C10="",D10=""),"",ROUND((D10-C10)*1440,0))) -> 51 | Q10: =IF($B10="","",I10*VLOOKUP(E10,Parametros!$B$18:$D$24,2,FALSE())) -> 300 | R10: =IF($B10="","",G10*VLOOKUP(E10,Parametros!$B$18:$D$24,3,FALSE())) -> 9.2 | S10: =IF($B10="","",Q10-R10) -> 290.8 | T10: =IF($B10="","",IF(S10>0,"G","P")) -> G | U10: =IF($B10="","",S10/Parametros!$C$8) -> 1.9386667 | V10: =IF($B10="","",Parametros!$C$6+SUM($S$7:S10)) -> 9297.72 | W10: =IF($B10="","",MAX(V10,W9)) -> 9297.72 | X10: =IF($B10="","",V10-W10) -> 0 | Y10: =IF($B10="","",X10/W10) -> 0 | Z10: =IF($B10="","",IF(T10="G",IF(N(Z9)>0,Z9+1,1),IF(N(Z9)<0,Z9-1,-1))) -> 1 | AA10: =IF($B10="","",B10-WEEKDAY(B10,2)+1) -> 46258 | AB10: =IF($B10="","",DATE(YEAR(B10),MONTH(B10),1)) -> 46235 | AC10: =IF($B10="","",CHOOSE(WEEKDAY(B10,2),"Lunes","Martes","Miércoles","Jueves","Viernes","Sábado","Domingo")) -> Miércoles | AD10: =IF($B10="","",HOUR(C10)) -> 11 | AE10: =IF($B10="","",IF(O10<>O9,MAX(V10-S10,V10),MAX(V10,AE9))) -> 9297.72 | AF10: =IF($B10="","",V10-AE10) -> 0 | AG10: =IF($B10="","",IF(O10<>O9,IF(T10="G",1,-1),IF(T10="G",IF(N(AG9)>0,AG9+1,1),IF(N(AG9)<0,AG9-1,-1)))) -> 1
A11: =IF(B11="","",ROW()-6) -> 5 | B11: 46262 | C11: 0.44236111 | D11: 0.45902778 | E11: MCL | F11: L | G11: 5 | H11: Giro+VC | I11: -150 | J11: 15 | K11: 33 | L11: SI | O11: =IF($B11="","",INT((A11-1)/Parametros!$C$10)+1) -> 1 | P11: =IF($B11="","",IF(OR(C11="",D11=""),"",ROUND((D11-C11)*1440,0))) -> 24 | Q11: =IF($B11="","",I11*VLOOKUP(E11,Parametros!$B$18:$D$24,2,FALSE())) -> -150 | R11: =IF($B11="","",G11*VLOOKUP(E11,Parametros!$B$18:$D$24,3,FALSE())) -> 9.2 | S11: =IF($B11="","",Q11-R11) -> -159.2 | T11: =IF($B11="","",IF(S11>0,"G","P")) -> P | U11: =IF($B11="","",S11/Parametros!$C$8) -> -1.0613333 | V11: =IF($B11="","",Parametros!$C$6+SUM($S$7:S11)) -> 9138.52 | W11: =IF($B11="","",MAX(V11,W10)) -> 9297.72 | X11: =IF($B11="","",V11-W11) -> -159.2 | Y11: =IF($B11="","",X11/W11) -> -0.017122477 | Z11: =IF($B11="","",IF(T11="G",IF(N(Z10)>0,Z10+1,1),IF(N(Z10)<0,Z10-1,-1))) -> -1 | AA11: =IF($B11="","",B11-WEEKDAY(B11,2)+1) -> 46258 | AB11: =IF($B11="","",DATE(YEAR(B11),MONTH(B11),1)) -> 46235 | AC11: =IF($B11="","",CHOOSE(WEEKDAY(B11,2),"Lunes","Martes","Miércoles","Jueves","Viernes","Sábado","Domingo")) -> Viernes | AD11: =IF($B11="","",HOUR(C11)) -> 10 | AE11: =IF($B11="","",IF(O11<>O10,MAX(V11-S11,V11),MAX(V11,AE10))) -> 9297.72 | AF11: =IF($B11="","",V11-AE11) -> -159.2 | AG11: =IF($B11="","",IF(O11<>O10,IF(T11="G",1,-1),IF(T11="G",IF(N(AG10)>0,AG10+1,1),IF(N(AG10)<0,AG10-1,-1)))) -> -1
A12: =IF(B12="","",ROW()-6) -> 6 | B12: 46265 | C12: 0.51597222 | D12: 0.60763889 | E12: MCL | F12: L | G12: 5 | H12: Giro+VC | I12: 300 | J12: 60 | K12: 14 | L12: SI | O12: =IF($B12="","",INT((A12-1)/Parametros!$C$10)+1) -> 1 | P12: =IF($B12="","",IF(OR(C12="",D12=""),"",ROUND((D12-C12)*1440,0))) -> 132 | Q12: =IF($B12="","",I12*VLOOKUP(E12,Parametros!$B$18:$D$24,2,FALSE())) -> 300 | R12: =IF($B12="","",G12*VLOOKUP(E12,Parametros!$B$18:$D$24,3,FALSE())) -> 9.2 | S12: =IF($B12="","",Q12-R12) -> 290.8 | T12: =IF($B12="","",IF(S12>0,"G","P")) -> G | U12: =IF($B12="","",S12/Parametros!$C$8) -> 1.9386667 | V12: =IF($B12="","",Parametros!$C$6+SUM($S$7:S12)) -> 9429.32 | W12: =IF($B12="","",MAX(V12,W11)) -> 9429.32 | X12: =IF($B12="","",V12-W12) -> 0 | Y12: =IF($B12="","",X12/W12) -> 0 | Z12: =IF($B12="","",IF(T12="G",IF(N(Z11)>0,Z11+1,1),IF(N(Z11)<0,Z11-1,-1))) -> 1 | AA12: =IF($B12="","",B12-WEEKDAY(B12,2)+1) -> 46265 | AB12: =IF($B12="","",DATE(YEAR(B12),MONTH(B12),1)) -> 46235 | AC12: =IF($B12="","",CHOOSE(WEEKDAY(B12,2),"Lunes","Martes","Miércoles","Jueves","Viernes","Sábado","Domingo")) -> Lunes | AD12: =IF($B12="","",HOUR(C12)) -> 12 | AE12: =IF($B12="","",IF(O12<>O11,MAX(V12-S12,V12),MAX(V12,AE11))) -> 9429.32 | AF12: =IF($B12="","",V12-AE12) -> 0 | AG12: =IF($B12="","",IF(O12<>O11,IF(T12="G",1,-1),IF(T12="G",IF(N(AG11)>0,AG11+1,1),IF(N(AG11)<0,AG11-1,-1)))) -> 1
A13: =IF(B13="","",ROW()-6) -> 7 | B13: 46268 | C13: 0.55347222 | D13: 0.56180556 | E13: MCL | F13: C | G13: 5 | H13: ESTRUC+VC | I13: -150 | K13: 30 | L13: NO | O13: =IF($B13="","",INT((A13-1)/Parametros!$C$10)+1) -> 1 | P13: =IF($B13="","",IF(OR(C13="",D13=""),"",ROUND((D13-C13)*1440,0))) -> 12 | Q13: =IF($B13="","",I13*VLOOKUP(E13,Parametros!$B$18:$D$24,2,FALSE())) -> -150 | R13: =IF($B13="","",G13*VLOOKUP(E13,Parametros!$B$18:$D$24,3,FALSE())) -> 9.2 | S13: =IF($B13="","",Q13-R13) -> -159.2 | T13: =IF($B13="","",IF(S13>0,"G","P")) -> P | U13: =IF($B13="","",S13/Parametros!$C$8) -> -1.0613333 | V13: =IF($B13="","",Parametros!$C$6+SUM($S$7:S13)) -> 9270.12 | W13: =IF($B13="","",MAX(V13,W12)) -> 9429.32 | X13: =IF($B13="","",V13-W13) -> -159.2 | Y13: =IF($B13="","",X13/W13) -> -0.016883508 | Z13: =IF($B13="","",IF(T13="G",IF(N(Z12)>0,Z12+1,1),IF(N(Z12)<0,Z12-1,-1))) -> -1 | AA13: =IF($B13="","",B13-WEEKDAY(B13,2)+1) -> 46265 | AB13: =IF($B13="","",DATE(YEAR(B13),MONTH(B13),1)) -> 46266 | AC13: =IF($B13="","",CHOOSE(WEEKDAY(B13,2),"Lunes","Martes","Miércoles","Jueves","Viernes","Sábado","Domingo")) -> Jueves | AD13: =IF($B13="","",HOUR(C13)) -> 13 | AE13: =IF($B13="","",IF(O13<>O12,MAX(V13-S13,V13),MAX(V13,AE12))) -> 9429.32 | AF13: =IF($B13="","",V13-AE13) -> -159.2 | AG13: =IF($B13="","",IF(O13<>O12,IF(T13="G",1,-1),IF(T13="G",IF(N(AG12)>0,AG12+1,1),IF(N(AG12)<0,AG12-1,-1)))) -> -1
A14: =IF(B14="","",ROW()-6) -> 8 | B14: 46274 | C14: 0.45972222 | D14: 0.47152778 | E14: MCL | F14: C | G14: 5 | H14: Giro+VC | I14: -150 | J14: 22 | K14: 36 | L14: SI | O14: =IF($B14="","",INT((A14-1)/Parametros!$C$10)+1) -> 1 | P14: =IF($B14="","",IF(OR(C14="",D14=""),"",ROUND((D14-C14)*1440,0))) -> 17 | Q14: =IF($B14="","",I14*VLOOKUP(E14,Parametros!$B$18:$D$24,2,FALSE())) -> -150 | R14: =IF($B14="","",G14*VLOOKUP(E14,Parametros!$B$18:$D$24,3,FALSE())) -> 9.2 | S14: =IF($B14="","",Q14-R14) -> -159.2 | T14: =IF($B14="","",IF(S14>0,"G","P")) -> P | U14: =IF($B14="","",S14/Parametros!$C$8) -> -1.0613333 | V14: =IF($B14="","",Parametros!$C$6+SUM($S$7:S14)) -> 9110.92 | W14: =IF($B14="","",MAX(V14,W13)) -> 9429.32 | X14: =IF($B14="","",V14-W14) -> -318.4 | Y14: =IF($B14="","",X14/W14) -> -0.033767016 | Z14: =IF($B14="","",IF(T14="G",IF(N(Z13)>0,Z13+1,1),IF(N(Z13)<0,Z13-1,-1))) -> -2 | AA14: =IF($B14="","",B14-WEEKDAY(B14,2)+1) -> 46272 | AB14: =IF($B14="","",DATE(YEAR(B14),MONTH(B14),1)) -> 46266 | AC14: =IF($B14="","",CHOOSE(WEEKDAY(B14,2),"Lunes","Martes","Miércoles","Jueves","Viernes","Sábado","Domingo")) -> Miércoles | AD14: =IF($B14="","",HOUR(C14)) -> 11 | AE14: =IF($B14="","",IF(O14<>O13,MAX(V14-S14,V14),MAX(V14,AE13))) -> 9429.32 | AF14: =IF($B14="","",V14-AE14) -> -318.4 | AG14: =IF($B14="","",IF(O14<>O13,IF(T14="G",1,-1),IF(T14="G",IF(N(AG13)>0,AG13+1,1),IF(N(AG13)<0,AG13-1,-1)))) -> -2
A15: =IF(B15="","",ROW()-6) -> 9 | B15: 46276 | C15: 0.44583333 | D15: 0.54861111 | E15: MCL | F15: L | G15: 3 | H15: Giro+VC | I15: 300 | J15: 100 | L15: SI | O15: =IF($B15="","",INT((A15-1)/Parametros!$C$10)+1) -> 1 | P15: =IF($B15="","",IF(OR(C15="",D15=""),"",ROUND((D15-C15)*1440,0))) -> 148 | Q15: =IF($B15="","",I15*VLOOKUP(E15,Parametros!$B$18:$D$24,2,FALSE())) -> 300 | R15: =IF($B15="","",G15*VLOOKUP(E15,Parametros!$B$18:$D$24,3,FALSE())) -> 5.52 | S15: =IF($B15="","",Q15-R15) -> 294.48 | T15: =IF($B15="","",IF(S15>0,"G","P")) -> G | U15: =IF($B15="","",S15/Parametros!$C$8) -> 1.9632 | V15: =IF($B15="","",Parametros!$C$6+SUM($S$7:S15)) -> 9405.4 | W15: =IF($B15="","",MAX(V15,W14)) -> 9429.32 | X15: =IF($B15="","",V15-W15) -> -23.92 | Y15: =IF($B15="","",X15/W15) -> -0.0025367683 | Z15: =IF($B15="","",IF(T15="G",IF(N(Z14)>0,Z14+1,1),IF(N(Z14)<0,Z14-1,-1))) -> 1 | AA15: =IF($B15="","",B15-WEEKDAY(B15,2)+1) -> 46272 | AB15: =IF($B15="","",DATE(YEAR(B15),MONTH(B15),1)) -> 46266 | AC15: =IF($B15="","",CHOOSE(WEEKDAY(B15,2),"Lunes","Martes","Miércoles","Jueves","Viernes","Sábado","Domingo")) -> Viernes | AD15: =IF($B15="","",HOUR(C15)) -> 10 | AE15: =IF($B15="","",IF(O15<>O14,MAX(V15-S15,V15),MAX(V15,AE14))) -> 9429.32 | AF15: =IF($B15="","",V15-AE15) -> -23.92 | AG15: =IF($B15="","",IF(O15<>O14,IF(T15="G",1,-1),IF(T15="G",IF(N(AG14)>0,AG14+1,1),IF(N(AG14)<0,AG14-1,-1)))) -> 1
A16: =IF(B16="","",ROW()-6) -> 10 | B16: 46286 | C16: 0.45555556 | D16: 0.45833333 | E16: MCL | F16: L | G16: 5 | H16: Giro+VC | I16: -150 | J16: 10 | K16: 150 | L16: SI | O16: =IF($B16="","",INT((A16-1)/Parametros!$C$10)+1) -> 1 | P16: =IF($B16="","",IF(OR(C16="",D16=""),"",ROUND((D16-C16)*1440,0))) -> 4 | Q16: =IF($B16="","",I16*VLOOKUP(E16,Parametros!$B$18:$D$24,2,FALSE())) -> -150 | R16: =IF($B16="","",G16*VLOOKUP(E16,Parametros!$B$18:$D$24,3,FALSE())) -> 9.2 | S16: =IF($B16="","",Q16-R16) -> -159.2 | T16: =IF($B16="","",IF(S16>0,"G","P")) -> P | U16: =IF($B16="","",S16/Parametros!$C$8) -> -1.0613333 | V16: =IF($B16="","",Parametros!$C$6+SUM($S$7:S16)) -> 9246.2 | W16: =IF($B16="","",MAX(V16,W15)) -> 9429.32 | X16: =IF($B16="","",V16-W16) -> -183.12 | Y16: =IF($B16="","",X16/W16) -> -0.019420276 | Z16: =IF($B16="","",IF(T16="G",IF(N(Z15)>0,Z15+1,1),IF(N(Z15)<0,Z15-1,-1))) -> -1 | AA16: =IF($B16="","",B16-WEEKDAY(B16,2)+1) -> 46286 | AB16: =IF($B16="","",DATE(YEAR(B16),MONTH(B16),1)) -> 46266 | AC16: =IF($B16="","",CHOOSE(WEEKDAY(B16,2),"Lunes","Martes","Miércoles","Jueves","Viernes","Sábado","Domingo")) -> Lunes | AD16: =IF($B16="","",HOUR(C16)) -> 10 | AE16: =IF($B16="","",IF(O16<>O15,MAX(V16-S16,V16),MAX(V16,AE15))) -> 9429.32 | AF16: =IF($B16="","",V16-AE16) -> -183.12 | AG16: =IF($B16="","",IF(O16<>O15,IF(T16="G",1,-1),IF(T16="G",IF(N(AG15)>0,AG15+1,1),IF(N(AG15)<0,AG15-1,-1)))) -> -1
A17: =IF(B17="","",ROW()-6) -> 11 | B17: 46286 | C17: 0.4875 | D17: 0.49444444 | E17: MCL | F17: C | G17: 5 | H17: ESTRUC+VC | I17: -150 | J17: 50 | K17: 62 | L17: SI | O17: =IF($B17="","",INT((A17-1)/Parametros!$C$10)+1) -> 1 | P17: =IF($B17="","",IF(OR(C17="",D17=""),"",ROUND((D17-C17)*1440,0))) -> 10 | Q17: =IF($B17="","",I17*VLOOKUP(E17,Parametros!$B$18:$D$24,2,FALSE())) -> -150 | R17: =IF($B17="","",G17*VLOOKUP(E17,Parametros!$B$18:$D$24,3,FALSE())) -> 9.2 | S17: =IF($B17="","",Q17-R17) -> -159.2 | T17: =IF($B17="","",IF(S17>0,"G","P")) -> P | U17: =IF($B17="","",S17/Parametros!$C$8) -> -1.0613333 | V17: =IF($B17="","",Parametros!$C$6+SUM($S$7:S17)) -> 9087 | W17: =IF($B17="","",MAX(V17,W16)) -> 9429.32 | X17: =IF($B17="","",V17-W17) -> -342.32 | Y17: =IF($B17="","",X17/W17) -> -0.036303784 | Z17: =IF($B17="","",IF(T17="G",IF(N(Z16)>0,Z16+1,1),IF(N(Z16)<0,Z16-1,-1))) -> -2 | AA17: =IF($B17="","",B17-WEEKDAY(B17,2)+1) -> 46286 | AB17: =IF($B17="","",DATE(YEAR(B17),MONTH(B17),1)) -> 46266 | AC17: =IF($B17="","",CHOOSE(WEEKDAY(B17,2),"Lunes","Martes","Miércoles","Jueves","Viernes","Sábado","Domingo")) -> Lunes | AD17: =IF($B17="","",HOUR(C17)) -> 11 | AE17: =IF($B17="","",IF(O17<>O16,MAX(V17-S17,V17),MAX(V17,AE16))) -> 9429.32 | AF17: =IF($B17="","",V17-AE17) -> -342.32 | AG17: =IF($B17="","",IF(O17<>O16,IF(T17="G",1,-1),IF(T17="G",IF(N(AG16)>0,AG16+1,1),IF(N(AG16)<0,AG16-1,-1)))) -> -2
A18: =IF(B18="","",ROW()-6) -> 12 | B18: 46289 | C18: 0.49722222 | D18: 0.52013889 | E18: MCL | F18: L | G18: 3 | H18: ESTRUC+VC | I18: 300 | J18: 303 | K18: 3 | L18: SI | O18: =IF($B18="","",INT((A18-1)/Parametros!$C$10)+1) -> 1 | P18: =IF($B18="","",IF(OR(C18="",D18=""),"",ROUND((D18-C18)*1440,0))) -> 33 | Q18: =IF($B18="","",I18*VLOOKUP(E18,Parametros!$B$18:$D$24,2,FALSE())) -> 300 | R18: =IF($B18="","",G18*VLOOKUP(E18,Parametros!$B$18:$D$24,3,FALSE())) -> 5.52 | S18: =IF($B18="","",Q18-R18) -> 294.48 | T18: =IF($B18="","",IF(S18>0,"G","P")) -> G | U18: =IF($B18="","",S18/Parametros!$C$8) -> 1.9632 | V18: =IF($B18="","",Parametros!$C$6+SUM($S$7:S18)) -> 9381.48 | W18: =IF($B18="","",MAX(V18,W17)) -> 9429.32 | X18: =IF($B18="","",V18-W18) -> -47.84 | Y18: =IF($B18="","",X18/W18) -> -0.0050735366 | Z18: =IF($B18="","",IF(T18="G",IF(N(Z17)>0,Z17+1,1),IF(N(Z17)<0,Z17-1,-1))) -> 1 | AA18: =IF($B18="","",B18-WEEKDAY(B18,2)+1) -> 46286 | AB18: =IF($B18="","",DATE(YEAR(B18),MONTH(B18),1)) -> 46266 | AC18: =IF($B18="","",CHOOSE(WEEKDAY(B18,2),"Lunes","Martes","Miércoles","Jueves","Viernes","Sábado","Domingo")) -> Jueves | AD18: =IF($B18="","",HOUR(C18)) -> 11 | AE18: =IF($B18="","",IF(O18<>O17,MAX(V18-S18,V18),MAX(V18,AE17))) -> 9429.32 | AF18: =IF($B18="","",V18-AE18) -> -47.84 | AG18: =IF($B18="","",IF(O18<>O17,IF(T18="G",1,-1),IF(T18="G",IF(N(AG17)>0,AG17+1,1),IF(N(AG17)<0,AG17-1,-1)))) -> 1
A19: =IF(B19="","",ROW()-6) -> 13 | B19: 46293 | C19: 0.51736111 | D19: 0.54166667 | E19: MCL | F19: L | G19: 5 | H19: ESTRUC+VC | I19: -150 | J19: 29 | K19: 32 | L19: SI | O19: =IF($B19="","",INT((A19-1)/Parametros!$C$10)+1) -> 1 | P19: =IF($B19="","",IF(OR(C19="",D19=""),"",ROUND((D19-C19)*1440,0))) -> 35 | Q19: =IF($B19="","",I19*VLOOKUP(E19,Parametros!$B$18:$D$24,2,FALSE())) -> -150 | R19: =IF($B19="","",G19*VLOOKUP(E19,Parametros!$B$18:$D$24,3,FALSE())) -> 9.2 | S19: =IF($B19="","",Q19-R19) -> -159.2 | T19: =IF($B19="","",IF(S19>0,"G","P")) -> P | U19: =IF($B19="","",S19/Parametros!$C$8) -> -1.0613333 | V19: =IF($B19="","",Parametros!$C$6+SUM($S$7:S19)) -> 9222.28 | W19: =IF($B19="","",MAX(V19,W18)) -> 9429.32 | X19: =IF($B19="","",V19-W19) -> -207.04 | Y19: =IF($B19="","",X19/W19) -> -0.021957045 | Z19: =IF($B19="","",IF(T19="G",IF(N(Z18)>0,Z18+1,1),IF(N(Z18)<0,Z18-1,-1))) -> -1 | AA19: =IF($B19="","",B19-WEEKDAY(B19,2)+1) -> 46293 | AB19: =IF($B19="","",DATE(YEAR(B19),MONTH(B19),1)) -> 46266 | AC19: =IF($B19="","",CHOOSE(WEEKDAY(B19,2),"Lunes","Martes","Miércoles","Jueves","Viernes","Sábado","Domingo")) -> Lunes | AD19: =IF($B19="","",HOUR(C19)) -> 12 | AE19: =IF($B19="","",IF(O19<>O18,MAX(V19-S19,V19),MAX(V19,AE18))) -> 9429.32 | AF19: =IF($B19="","",V19-AE19) -> -207.04 | AG19: =IF($B19="","",IF(O19<>O18,IF(T19="G",1,-1),IF(T19="G",IF(N(AG18)>0,AG18+1,1),IF(N(AG18)<0,AG18-1,-1)))) -> -1
A20: =IF(B20="","",ROW()-6) -> 14 | B20: 46294 | C20: 0.51666667 | D20: 0.53263889 | E20: MCL | F20: L | G20: 3 | H20: ESTRUC+VC | I20: -150 | J20: 0 | K20: 54 | L20: SI | O20: =IF($B20="","",INT((A20-1)/Parametros!$C$10)+1) -> 1 | P20: =IF($B20="","",IF(OR(C20="",D20=""),"",ROUND((D20-C20)*1440,0))) -> 23 | Q20: =IF($B20="","",I20*VLOOKUP(E20,Parametros!$B$18:$D$24,2,FALSE())) -> -150 | R20: =IF($B20="","",G20*VLOOKUP(E20,Parametros!$B$18:$D$24,3,FALSE())) -> 5.52 | S20: =IF($B20="","",Q20-R20) -> -155.52 | T20: =IF($B20="","",IF(S20>0,"G","P")) -> P | U20: =IF($B20="","",S20/Parametros!$C$8) -> -1.0368 | V20: =IF($B20="","",Parametros!$C$6+SUM($S$7:S20)) -> 9066.76 | W20: =IF($B20="","",MAX(V20,W19)) -> 9429.32 | X20: =IF($B20="","",V20-W20) -> -362.56 | Y20: =IF($B20="","",X20/W20) -> -0.038450281 | Z20: =IF($B20="","",IF(T20="G",IF(N(Z19)>0,Z19+1,1),IF(N(Z19)<0,Z19-1,-1))) -> -2 | AA20: =IF($B20="","",B20-WEEKDAY(B20,2)+1) -> 46293 | AB20: =IF($B20="","",DATE(YEAR(B20),MONTH(B20),1)) -> 46266 | AC20: =IF($B20="","",CHOOSE(WEEKDAY(B20,2),"Lunes","Martes","Miércoles","Jueves","Viernes","Sábado","Domingo")) -> Martes | AD20: =IF($B20="","",HOUR(C20)) -> 12 | AE20: =IF($B20="","",IF(O20<>O19,MAX(V20-S20,V20),MAX(V20,AE19))) -> 9429.32 | AF20: =IF($B20="","",V20-AE20) -> -362.56 | AG20: =IF($B20="","",IF(O20<>O19,IF(T20="G",1,-1),IF(T20="G",IF(N(AG19)>0,AG19+1,1),IF(N(AG19)<0,AG19-1,-1)))) -> -2
A21: =IF(B21="","",ROW()-6) -> 15 | B21: 46303 | C21: 0.51041667 | D21: 0.52083333 | E21: MCL | F21: L | G21: 5 | H21: ESTRUC+VC | I21: -150 | L21: SI | O21: =IF($B21="","",INT((A21-1)/Parametros!$C$10)+1) -> 1 | P21: =IF($B21="","",IF(OR(C21="",D21=""),"",ROUND((D21-C21)*1440,0))) -> 15 | Q21: =IF($B21="","",I21*VLOOKUP(E21,Parametros!$B$18:$D$24,2,FALSE())) -> -150 | R21: =IF($B21="","",G21*VLOOKUP(E21,Parametros!$B$18:$D$24,3,FALSE())) -> 9.2 | S21: =IF($B21="","",Q21-R21) -> -159.2 | T21: =IF($B21="","",IF(S21>0,"G","P")) -> P | U21: =IF($B21="","",S21/Parametros!$C$8) -> -1.0613333 | V21: =IF($B21="","",Parametros!$C$6+SUM($S$7:S21)) -> 8907.56 | W21: =IF($B21="","",MAX(V21,W20)) -> 9429.32 | X21: =IF($B21="","",V21-W21) -> -521.76 | Y21: =IF($B21="","",X21/W21) -> -0.055333789 | Z21: =IF($B21="","",IF(T21="G",IF(N(Z20)>0,Z20+1,1),IF(N(Z20)<0,Z20-1,-1))) -> -3 | AA21: =IF($B21="","",B21-WEEKDAY(B21,2)+1) -> 46300 | AB21: =IF($B21="","",DATE(YEAR(B21),MONTH(B21),1)) -> 46296 | AC21: =IF($B21="","",CHOOSE(WEEKDAY(B21,2),"Lunes","Martes","Miércoles","Jueves","Viernes","Sábado","Domingo")) -> Jueves | AD21: =IF($B21="","",HOUR(C21)) -> 12 | AE21: =IF($B21="","",IF(O21<>O20,MAX(V21-S21,V21),MAX(V21,AE20))) -> 9429.32 | AF21: =IF($B21="","",V21-AE21) -> -521.76 | AG21: =IF($B21="","",IF(O21<>O20,IF(T21="G",1,-1),IF(T21="G",IF(N(AG20)>0,AG20+1,1),IF(N(AG20)<0,AG20-1,-1)))) -> -3
A22: =IF(B22="","",ROW()-6) -> 16 | B22: 46304 | C22: 0.51736111 | D22: 0.55277778 | E22: MCL | F22: L | G22: 5 | H22: ESTRUC+VC | I22: -150 | L22: SI | O22: =IF($B22="","",INT((A22-1)/Parametros!$C$10)+1) -> 1 | P22: =IF($B22="","",IF(OR(C22="",D22=""),"",ROUND((D22-C22)*1440,0))) -> 51 | Q22: =IF($B22="","",I22*VLOOKUP(E22,Parametros!$B$18:$D$24,2,FALSE())) -> -150 | R22: =IF($B22="","",G22*VLOOKUP(E22,Parametros!$B$18:$D$24,3,FALSE())) -> 9.2 | S22: =IF($B22="","",Q22-R22) -> -159.2 | T22: =IF($B22="","",IF(S22>0,"G","P")) -> P | U22: =IF($B22="","",S22/Parametros!$C$8) -> -1.0613333 | V22: =IF($B22="","",Parametros!$C$6+SUM($S$7:S22)) -> 8748.36 | W22: =IF($B22="","",MAX(V22,W21)) -> 9429.32 | X22: =IF($B22="","",V22-W22) -> -680.96 | Y22: =IF($B22="","",X22/W22) -> -0.072217297 | Z22: =IF($B22="","",IF(T22="G",IF(N(Z21)>0,Z21+1,1),IF(N(Z21)<0,Z21-1,-1))) -> -4 | AA22: =IF($B22="","",B22-WEEKDAY(B22,2)+1) -> 46300 | AB22: =IF($B22="","",DATE(YEAR(B22),MONTH(B22),1)) -> 46296 | AC22: =IF($B22="","",CHOOSE(WEEKDAY(B22,2),"Lunes","Martes","Miércoles","Jueves","Viernes","Sábado","Domingo")) -> Viernes | AD22: =IF($B22="","",HOUR(C22)) -> 12 | AE22: =IF($B22="","",IF(O22<>O21,MAX(V22-S22,V22),MAX(V22,AE21))) -> 9429.32 | AF22: =IF($B22="","",V22-AE22) -> -680.96 | AG22: =IF($B22="","",IF(O22<>O21,IF(T22="G",1,-1),IF(T22="G",IF(N(AG21)>0,AG21+1,1),IF(N(AG21)<0,AG21-1,-1)))) -> -4
A23: =IF(B23="","",ROW()-6) | O23: =IF($B23="","",INT((A23-1)/Parametros!$C$10)+1) | P23: =IF($B23="","",IF(OR(C23="",D23=""),"",ROUND((D23-C23)*1440,0))) | Q23: =IF($B23="","",I23*VLOOKUP(E23,Parametros!$B$18:$D$24,2,FALSE())) | R23: =IF($B23="","",G23*VLOOKUP(E23,Parametros!$B$18:$D$24,3,FALSE())) | S23: =IF($B23="","",Q23-R23) | T23: =IF($B23="","",IF(S23>0,"G","P")) | U23: =IF($B23="","",S23/Parametros!$C$8) | V23: =IF($B23="","",Parametros!$C$6+SUM($S$7:S23)) | W23: =IF($B23="","",MAX(V23,W22)) | X23: =IF($B23="","",V23-W23) | Y23: =IF($B23="","",X23/W23) | Z23: =IF($B23="","",IF(T23="G",IF(N(Z22)>0,Z22+1,1),IF(N(Z22)<0,Z22-1,-1))) | AA23: =IF($B23="","",B23-WEEKDAY(B23,2)+1) | AB23: =IF($B23="","",DATE(YEAR(B23),MONTH(B23),1)) | AC23: =IF($B23="","",CHOOSE(WEEKDAY(B23,2),"Lunes","Martes","Miércoles","Jueves","Viernes","Sábado","Domingo")) | AD23: =IF($B23="","",HOUR(C23)) | AE23: =IF($B23="","",IF(O23<>O22,MAX(V23-S23,V23),MAX(V23,AE22))) | AF23: =IF($B23="","",V23-AE23) | AG23: =IF($B23="","",IF(O23<>O22,IF(T23="G",1,-1),IF(T23="G",IF(N(AG22)>0,AG22+1,1),IF(N(AG22)<0,AG22-1,-1))))
A24: =IF(B24="","",ROW()-6) | O24: =IF($B24="","",INT((A24-1)/Parametros!$C$10)+1) | P24: =IF($B24="","",IF(OR(C24="",D24=""),"",ROUND((D24-C24)*1440,0))) | Q24: =IF($B24="","",I24*VLOOKUP(E24,Parametros!$B$18:$D$24,2,FALSE())) | R24: =IF($B24="","",G24*VLOOKUP(E24,Parametros!$B$18:$D$24,3,FALSE())) | S24: =IF($B24="","",Q24-R24) | T24: =IF($B24="","",IF(S24>0,"G","P")) | U24: =IF($B24="","",S24/Parametros!$C$8) | V24: =IF($B24="","",Parametros!$C$6+SUM($S$7:S24)) | W24: =IF($B24="","",MAX(V24,W23)) | X24: =IF($B24="","",V24-W24) | Y24: =IF($B24="","",X24/W24) | Z24: =IF($B24="","",IF(T24="G",IF(N(Z23)>0,Z23+1,1),IF(N(Z23)<0,Z23-1,-1))) | AA24: =IF($B24="","",B24-WEEKDAY(B24,2)+1) | AB24: =IF($B24="","",DATE(YEAR(B24),MONTH(B24),1)) | AC24: =IF($B24="","",CHOOSE(WEEKDAY(B24,2),"Lunes","Martes","Miércoles","Jueves","Viernes","Sábado","Domingo")) | AD24: =IF($B24="","",HOUR(C24)) | AE24: =IF($B24="","",IF(O24<>O23,MAX(V24-S24,V24),MAX(V24,AE23))) | AF24: =IF($B24="","",V24-AE24) | AG24: =IF($B24="","",IF(O24<>O23,IF(T24="G",1,-1),IF(T24="G",IF(N(AG23)>0,AG23+1,1),IF(N(AG23)<0,AG23-1,-1))))
A25: =IF(B25="","",ROW()-6) | O25: =IF($B25="","",INT((A25-1)/Parametros!$C$10)+1) | P25: =IF($B25="","",IF(OR(C25="",D25=""),"",ROUND((D25-C25)*1440,0))) | Q25: =IF($B25="","",I25*VLOOKUP(E25,Parametros!$B$18:$D$24,2,FALSE())) | R25: =IF($B25="","",G25*VLOOKUP(E25,Parametros!$B$18:$D$24,3,FALSE())) | S25: =IF($B25="","",Q25-R25) | T25: =IF($B25="","",IF(S25>0,"G","P")) | U25: =IF($B25="","",S25/Parametros!$C$8) | V25: =IF($B25="","",Parametros!$C$6+SUM($S$7:S25)) | W25: =IF($B25="","",MAX(V25,W24)) | X25: =IF($B25="","",V25-W25) | Y25: =IF($B25="","",X25/W25) | Z25: =IF($B25="","",IF(T25="G",IF(N(Z24)>0,Z24+1,1),IF(N(Z24)<0,Z24-1,-1))) | AA25: =IF($B25="","",B25-WEEKDAY(B25,2)+1) | AB25: =IF($B25="","",DATE(YEAR(B25),MONTH(B25),1)) | AC25: =IF($B25="","",CHOOSE(WEEKDAY(B25,2),"Lunes","Martes","Miércoles","Jueves","Viernes","Sábado","Domingo")) | AD25: =IF($B25="","",HOUR(C25)) | AE25: =IF($B25="","",IF(O25<>O24,MAX(V25-S25,V25),MAX(V25,AE24))) | AF25: =IF($B25="","",V25-AE25) | AG25: =IF($B25="","",IF(O25<>O24,IF(T25="G",1,-1),IF(T25="G",IF(N(AG24)>0,AG24+1,1),IF(N(AG24)<0,AG24-1,-1))))
A26: =IF(B26="","",ROW()-6) | O26: =IF($B26="","",INT((A26-1)/Parametros!$C$10)+1) | P26: =IF($B26="","",IF(OR(C26="",D26=""),"",ROUND((D26-C26)*1440,0))) | Q26: =IF($B26="","",I26*VLOOKUP(E26,Parametros!$B$18:$D$24,2,FALSE())) | R26: =IF($B26="","",G26*VLOOKUP(E26,Parametros!$B$18:$D$24,3,FALSE())) | S26: =IF($B26="","",Q26-R26) | T26: =IF($B26="","",IF(S26>0,"G","P")) | U26: =IF($B26="","",S26/Parametros!$C$8) | V26: =IF($B26="","",Parametros!$C$6+SUM($S$7:S26)) | W26: =IF($B26="","",MAX(V26,W25)) | X26: =IF($B26="","",V26-W26) | Y26: =IF($B26="","",X26/W26) | Z26: =IF($B26="","",IF(T26="G",IF(N(Z25)>0,Z25+1,1),IF(N(Z25)<0,Z25-1,-1))) | AA26: =IF($B26="","",B26-WEEKDAY(B26,2)+1) | AB26: =IF($B26="","",DATE(YEAR(B26),MONTH(B26),1)) | AC26: =IF($B26="","",CHOOSE(WEEKDAY(B26,2),"Lunes","Martes","Miércoles","Jueves","Viernes","Sábado","Domingo")) | AD26: =IF($B26="","",HOUR(C26)) | AE26: =IF($B26="","",IF(O26<>O25,MAX(V26-S26,V26),MAX(V26,AE25))) | AF26: =IF($B26="","",V26-AE26) | AG26: =IF($B26="","",IF(O26<>O25,IF(T26="G",1,-1),IF(T26="G",IF(N(AG25)>0,AG25+1,1),IF(N(AG25)<0,AG25-1,-1))))
A27: =IF(B27="","",ROW()-6) | O27: =IF($B27="","",INT((A27-1)/Parametros!$C$10)+1) | P27: =IF($B27="","",IF(OR(C27="",D27=""),"",ROUND((D27-C27)*1440,0))) | Q27: =IF($B27="","",I27*VLOOKUP(E27,Parametros!$B$18:$D$24,2,FALSE())) | R27: =IF($B27="","",G27*VLOOKUP(E27,Parametros!$B$18:$D$24,3,FALSE())) | S27: =IF($B27="","",Q27-R27) | T27: =IF($B27="","",IF(S27>0,"G","P")) | U27: =IF($B27="","",S27/Parametros!$C$8) | V27: =IF($B27="","",Parametros!$C$6+SUM($S$7:S27)) | W27: =IF($B27="","",MAX(V27,W26)) | X27: =IF($B27="","",V27-W27) | Y27: =IF($B27="","",X27/W27) | Z27: =IF($B27="","",IF(T27="G",IF(N(Z26)>0,Z26+1,1),IF(N(Z26)<0,Z26-1,-1))) | AA27: =IF($B27="","",B27-WEEKDAY(B27,2)+1) | AB27: =IF($B27="","",DATE(YEAR(B27),MONTH(B27),1)) | AC27: =IF($B27="","",CHOOSE(WEEKDAY(B27,2),"Lunes","Martes","Miércoles","Jueves","Viernes","Sábado","Domingo")) | AD27: =IF($B27="","",HOUR(C27)) | AE27: =IF($B27="","",IF(O27<>O26,MAX(V27-S27,V27),MAX(V27,AE26))) | AF27: =IF($B27="","",V27-AE27) | AG27: =IF($B27="","",IF(O27<>O26,IF(T27="G",1,-1),IF(T27="G",IF(N(AG26)>0,AG26+1,1),IF(N(AG26)<0,AG26-1,-1))))
A28: =IF(B28="","",ROW()-6) | O28: =IF($B28="","",INT((A28-1)/Parametros!$C$10)+1) | P28: =IF($B28="","",IF(OR(C28="",D28=""),"",ROUND((D28-C28)*1440,0))) | Q28: =IF($B28="","",I28*VLOOKUP(E28,Parametros!$B$18:$D$24,2,FALSE())) | R28: =IF($B28="","",G28*VLOOKUP(E28,Parametros!$B$18:$D$24,3,FALSE())) | S28: =IF($B28="","",Q28-R28) | T28: =IF($B28="","",IF(S28>0,"G","P")) | U28: =IF($B28="","",S28/Parametros!$C$8) | V28: =IF($B28="","",Parametros!$C$6+SUM($S$7:S28)) | W28: =IF($B28="","",MAX(V28,W27)) | X28: =IF($B28="","",V28-W28) | Y28: =IF($B28="","",X28/W28) | Z28: =IF($B28="","",IF(T28="G",IF(N(Z27)>0,Z27+1,1),IF(N(Z27)<0,Z27-1,-1))) | AA28: =IF($B28="","",B28-WEEKDAY(B28,2)+1) | AB28: =IF($B28="","",DATE(YEAR(B28),MONTH(B28),1)) | AC28: =IF($B28="","",CHOOSE(WEEKDAY(B28,2),"Lunes","Martes","Miércoles","Jueves","Viernes","Sábado","Domingo")) | AD28: =IF($B28="","",HOUR(C28)) | AE28: =IF($B28="","",IF(O28<>O27,MAX(V28-S28,V28),MAX(V28,AE27))) | AF28: =IF($B28="","",V28-AE28) | AG28: =IF($B28="","",IF(O28<>O27,IF(T28="G",1,-1),IF(T28="G",IF(N(AG27)>0,AG27+1,1),IF(N(AG27)<0,AG27-1,-1))))
A29: =IF(B29="","",ROW()-6) | O29: =IF($B29="","",INT((A29-1)/Parametros!$C$10)+1) | P29: =IF($B29="","",IF(OR(C29="",D29=""),"",ROUND((D29-C29)*1440,0))) | Q29: =IF($B29="","",I29*VLOOKUP(E29,Parametros!$B$18:$D$24,2,FALSE())) | R29: =IF($B29="","",G29*VLOOKUP(E29,Parametros!$B$18:$D$24,3,FALSE())) | S29: =IF($B29="","",Q29-R29) | T29: =IF($B29="","",IF(S29>0,"G","P")) | U29: =IF($B29="","",S29/Parametros!$C$8) | V29: =IF($B29="","",Parametros!$C$6+SUM($S$7:S29)) | W29: =IF($B29="","",MAX(V29,W28)) | X29: =IF($B29="","",V29-W29) | Y29: =IF($B29="","",X29/W29) | Z29: =IF($B29="","",IF(T29="G",IF(N(Z28)>0,Z28+1,1),IF(N(Z28)<0,Z28-1,-1))) | AA29: =IF($B29="","",B29-WEEKDAY(B29,2)+1) | AB29: =IF($B29="","",DATE(YEAR(B29),MONTH(B29),1)) | AC29: =IF($B29="","",CHOOSE(WEEKDAY(B29,2),"Lunes","Martes","Miércoles","Jueves","Viernes","Sábado","Domingo")) | AD29: =IF($B29="","",HOUR(C29)) | AE29: =IF($B29="","",IF(O29<>O28,MAX(V29-S29,V29),MAX(V29,AE28))) | AF29: =IF($B29="","",V29-AE29) | AG29: =IF($B29="","",IF(O29<>O28,IF(T29="G",1,-1),IF(T29="G",IF(N(AG28)>0,AG28+1,1),IF(N(AG28)<0,AG28-1,-1))))
A30: =IF(B30="","",ROW()-6) | O30: =IF($B30="","",INT((A30-1)/Parametros!$C$10)+1) | P30: =IF($B30="","",IF(OR(C30="",D30=""),"",ROUND((D30-C30)*1440,0))) | Q30: =IF($B30="","",I30*VLOOKUP(E30,Parametros!$B$18:$D$24,2,FALSE())) | R30: =IF($B30="","",G30*VLOOKUP(E30,Parametros!$B$18:$D$24,3,FALSE())) | S30: =IF($B30="","",Q30-R30) | T30: =IF($B30="","",IF(S30>0,"G","P")) | U30: =IF($B30="","",S30/Parametros!$C$8) | V30: =IF($B30="","",Parametros!$C$6+SUM($S$7:S30)) | W30: =IF($B30="","",MAX(V30,W29)) | X30: =IF($B30="","",V30-W30) | Y30: =IF($B30="","",X30/W30) | Z30: =IF($B30="","",IF(T30="G",IF(N(Z29)>0,Z29+1,1),IF(N(Z29)<0,Z29-1,-1))) | AA30: =IF($B30="","",B30-WEEKDAY(B30,2)+1) | AB30: =IF($B30="","",DATE(YEAR(B30),MONTH(B30),1)) | AC30: =IF($B30="","",CHOOSE(WEEKDAY(B30,2),"Lunes","Martes","Miércoles","Jueves","Viernes","Sábado","Domingo")) | AD30: =IF($B30="","",HOUR(C30)) | AE30: =IF($B30="","",IF(O30<>O29,MAX(V30-S30,V30),MAX(V30,AE29))) | AF30: =IF($B30="","",V30-AE30) | AG30: =IF($B30="","",IF(O30<>O29,IF(T30="G",1,-1),IF(T30="G",IF(N(AG29)>0,AG29+1,1),IF(N(AG29)<0,AG29-1,-1))))
A31: =IF(B31="","",ROW()-6) | O31: =IF($B31="","",INT((A31-1)/Parametros!$C$10)+1) | P31: =IF($B31="","",IF(OR(C31="",D31=""),"",ROUND((D31-C31)*1440,0))) | Q31: =IF($B31="","",I31*VLOOKUP(E31,Parametros!$B$18:$D$24,2,FALSE())) | R31: =IF($B31="","",G31*VLOOKUP(E31,Parametros!$B$18:$D$24,3,FALSE())) | S31: =IF($B31="","",Q31-R31) | T31: =IF($B31="","",IF(S31>0,"G","P")) | U31: =IF($B31="","",S31/Parametros!$C$8) | V31: =IF($B31="","",Parametros!$C$6+SUM($S$7:S31)) | W31: =IF($B31="","",MAX(V31,W30)) | X31: =IF($B31="","",V31-W31) | Y31: =IF($B31="","",X31/W31) | Z31: =IF($B31="","",IF(T31="G",IF(N(Z30)>0,Z30+1,1),IF(N(Z30)<0,Z30-1,-1))) | AA31: =IF($B31="","",B31-WEEKDAY(B31,2)+1) | AB31: =IF($B31="","",DATE(YEAR(B31),MONTH(B31),1)) | AC31: =IF($B31="","",CHOOSE(WEEKDAY(B31,2),"Lunes","Martes","Miércoles","Jueves","Viernes","Sábado","Domingo")) | AD31: =IF($B31="","",HOUR(C31)) | AE31: =IF($B31="","",IF(O31<>O30,MAX(V31-S31,V31),MAX(V31,AE30))) | AF31: =IF($B31="","",V31-AE31) | AG31: =IF($B31="","",IF(O31<>O30,IF(T31="G",1,-1),IF(T31="G",IF(N(AG30)>0,AG30+1,1),IF(N(AG30)<0,AG30-1,-1))))
A32: =IF(B32="","",ROW()-6) | O32: =IF($B32="","",INT((A32-1)/Parametros!$C$10)+1) | P32: =IF($B32="","",IF(OR(C32="",D32=""),"",ROUND((D32-C32)*1440,0))) | Q32: =IF($B32="","",I32*VLOOKUP(E32,Parametros!$B$18:$D$24,2,FALSE())) | R32: =IF($B32="","",G32*VLOOKUP(E32,Parametros!$B$18:$D$24,3,FALSE())) | S32: =IF($B32="","",Q32-R32) | T32: =IF($B32="","",IF(S32>0,"G","P")) | U32: =IF($B32="","",S32/Parametros!$C$8) | V32: =IF($B32="","",Parametros!$C$6+SUM($S$7:S32)) | W32: =IF($B32="","",MAX(V32,W31)) | X32: =IF($B32="","",V32-W32) | Y32: =IF($B32="","",X32/W32) | Z32: =IF($B32="","",IF(T32="G",IF(N(Z31)>0,Z31+1,1),IF(N(Z31)<0,Z31-1,-1))) | AA32: =IF($B32="","",B32-WEEKDAY(B32,2)+1) | AB32: =IF($B32="","",DATE(YEAR(B32),MONTH(B32),1)) | AC32: =IF($B32="","",CHOOSE(WEEKDAY(B32,2),"Lunes","Martes","Miércoles","Jueves","Viernes","Sábado","Domingo")) | AD32: =IF($B32="","",HOUR(C32)) | AE32: =IF($B32="","",IF(O32<>O31,MAX(V32-S32,V32),MAX(V32,AE31))) | AF32: =IF($B32="","",V32-AE32) | AG32: =IF($B32="","",IF(O32<>O31,IF(T32="G",1,-1),IF(T32="G",IF(N(AG31)>0,AG31+1,1),IF(N(AG31)<0,AG31-1,-1))))
A33: =IF(B33="","",ROW()-6) | O33: =IF($B33="","",INT((A33-1)/Parametros!$C$10)+1) | P33: =IF($B33="","",IF(OR(C33="",D33=""),"",ROUND((D33-C33)*1440,0))) | Q33: =IF($B33="","",I33*VLOOKUP(E33,Parametros!$B$18:$D$24,2,FALSE())) | R33: =IF($B33="","",G33*VLOOKUP(E33,Parametros!$B$18:$D$24,3,FALSE())) | S33: =IF($B33="","",Q33-R33) | T33: =IF($B33="","",IF(S33>0,"G","P")) | U33: =IF($B33="","",S33/Parametros!$C$8) | V33: =IF($B33="","",Parametros!$C$6+SUM($S$7:S33)) | W33: =IF($B33="","",MAX(V33,W32)) | X33: =IF($B33="","",V33-W33) | Y33: =IF($B33="","",X33/W33) | Z33: =IF($B33="","",IF(T33="G",IF(N(Z32)>0,Z32+1,1),IF(N(Z32)<0,Z32-1,-1))) | AA33: =IF($B33="","",B33-WEEKDAY(B33,2)+1) | AB33: =IF($B33="","",DATE(YEAR(B33),MONTH(B33),1)) | AC33: =IF($B33="","",CHOOSE(WEEKDAY(B33,2),"Lunes","Martes","Miércoles","Jueves","Viernes","Sábado","Domingo")) | AD33: =IF($B33="","",HOUR(C33)) | AE33: =IF($B33="","",IF(O33<>O32,MAX(V33-S33,V33),MAX(V33,AE32))) | AF33: =IF($B33="","",V33-AE33) | AG33: =IF($B33="","",IF(O33<>O32,IF(T33="G",1,-1),IF(T33="G",IF(N(AG32)>0,AG32+1,1),IF(N(AG32)<0,AG32-1,-1))))
A34: =IF(B34="","",ROW()-6) | O34: =IF($B34="","",INT((A34-1)/Parametros!$C$10)+1) | P34: =IF($B34="","",IF(OR(C34="",D34=""),"",ROUND((D34-C34)*1440,0))) | Q34: =IF($B34="","",I34*VLOOKUP(E34,Parametros!$B$18:$D$24,2,FALSE())) | R34: =IF($B34="","",G34*VLOOKUP(E34,Parametros!$B$18:$D$24,3,FALSE())) | S34: =IF($B34="","",Q34-R34) | T34: =IF($B34="","",IF(S34>0,"G","P")) | U34: =IF($B34="","",S34/Parametros!$C$8) | V34: =IF($B34="","",Parametros!$C$6+SUM($S$7:S34)) | W34: =IF($B34="","",MAX(V34,W33)) | X34: =IF($B34="","",V34-W34) | Y34: =IF($B34="","",X34/W34) | Z34: =IF($B34="","",IF(T34="G",IF(N(Z33)>0,Z33+1,1),IF(N(Z33)<0,Z33-1,-1))) | AA34: =IF($B34="","",B34-WEEKDAY(B34,2)+1) | AB34: =IF($B34="","",DATE(YEAR(B34),MONTH(B34),1)) | AC34: =IF($B34="","",CHOOSE(WEEKDAY(B34,2),"Lunes","Martes","Miércoles","Jueves","Viernes","Sábado","Domingo")) | AD34: =IF($B34="","",HOUR(C34)) | AE34: =IF($B34="","",IF(O34<>O33,MAX(V34-S34,V34),MAX(V34,AE33))) | AF34: =IF($B34="","",V34-AE34) | AG34: =IF($B34="","",IF(O34<>O33,IF(T34="G",1,-1),IF(T34="G",IF(N(AG33)>0,AG33+1,1),IF(N(AG33)<0,AG33-1,-1))))
... A506: =IF(B506="","",ROW()-6) | O506: =IF($B506="","",INT((A506-1)/Parametros!$C$10)+1) | P506: =IF($B506="","",IF(OR(C506="",D506=""),"",ROUND((D506-C506)*1440,0))) | Q506: =IF($B506="","",I506*VLOOKUP(E506,Parametros!$B$18:$D$24,2,FALSE())) | R506: =IF($B506="","",G506*VLOOKUP(E506,Parametros!$B$18:$D$24,3,FALSE())) | S506: =IF($B506="","",Q506-R506) | T506: =IF($B506="","",IF(S506>0,"G","P")) | U506: =IF($B506="","",S506/Parametros!$C$8) | V506: =IF($B506="","",Parametros!$C$6+SUM($S$7:S506)) | W506: =IF($B506="","",MAX(V506,W505)) | X506: =IF($B506="","",V506-W506) | Y506: =IF($B506="","",X506/W506) | Z506: =IF($B506="","",IF(T506="G",IF(N(Z505)>0,Z505+1,1),IF(N(Z505)<0,Z505-1,-1))) | AA506: =IF($B506="","",B506-WEEKDAY(B506,2)+1) | AB506: =IF($B506="","",DATE(YEAR(B506),MONTH(B506),1)) | AC506: =IF($B506="","",CHOOSE(WEEKDAY(B506,2),"Lunes","Martes","Miércoles","Jueves","Viernes","Sábado","Domingo")) | AD506: =IF($B506="","",HOUR(C506)) | AE506: =IF($B506="","",IF(O506<>O505,MAX(V506-S506,V506),MAX(V506,AE505))) | AF506: =IF($B506="","",V506-AE506) | AG506: =IF($B506="","",IF(O506<>O505,IF(T506="G",1,-1),IF(T506="G",IF(N(AG505)>0,AG505+1,1),IF(N(AG505)<0,AG505-1,-1))))

Sheet Bloques
B2: Bloques de 20 operaciones
B3: Cada bloque es una muestra de 20 operaciones. Compara cada bloque con el global y con tus metas (Parametros).
B6: BLOQUE EN CURSO vs GLOBAL
B8: Muestra | D8: Operaciones | E8: % acierto | F8: Profit factor | G8: Gan. / Perd. | I8: Neto $ | K8: Esperanza $ | M8: Máx. DD $ | O8: Disciplina | R8: =IF(Dashboard!O39=0,"",IF(Dashboard!O38=1,"Primer bloque: por ahora coincide con el global",IF(INDEX($L$15:$L$39,Dashboard!O38)>=Dashboard!E26,"▲ El bloque actual va MEJOR que el global","▼ El bloque actual va por debajo del global"))) -> Primer bloque: por ahora coincide con el global
B9: ="Bloque "&Dashboard!O38 -> Bloque 1 | D9: =INDEX($C$15:$C$39,Dashboard!O38) -> 16 | E9: =INDEX($J$15:$J$39,Dashboard!O38) -> 0.375 | F9: =INDEX($L$15:$L$39,Dashboard!O38) -> 1.103153 | G9: =INDEX($H$15:$H$39,Dashboard!O38)&" / "&INDEX($I$15:$I$39,Dashboard!O38) -> 6 / 10 | I9: =INDEX($K$15:$K$39,Dashboard!O38) -> 163.84 | K9: =INDEX($M$15:$M$39,Dashboard!O38) -> 10.24 | M9: =INDEX($O$15:$O$39,Dashboard!O38) -> -680.96 | O9: =INDEX($Q$15:$Q$39,Dashboard!O38) -> 0.9375
B10: ="Global" -> Global | D10: =Dashboard!E18 -> 16 | E10: =Dashboard!E21 -> 0.375 | F10: =Dashboard!E26 -> 1.103153 | G10: =Dashboard!E19&" / "&Dashboard!E20 -> 6 / 10 | I10: =Dashboard!E23 -> 163.84 | K10: =Dashboard!J21 -> 10.24 | M10: =Dashboard!O34 -> -680.96 | O10: =Dashboard!J25 -> 0.9375
B12: DETALLE POR BLOQUE
B14: Bloque | C14: Ops | D14: Progreso | E14: Estado | F14: Desde | G14: Hasta | H14: Gan. | I14: Perd. | J14: % acierto | K14: Neto $ | L14: Profit factor | M14: Esperanza $ | N14: Esperanza R | O14: Máx. DD bloque $ | P14: Peor racha | Q14: Disciplina | R14: Capital al cierre $ | S14: Meta PF | T14: Meta acierto | U14: Meta disc.
B15: 1 | C15: =COUNTIFS('CARGAR OPERACIONES'!$O$7:$O$506,$B15) -> 16 | D15: =IF(C15=0,"",C15/Parametros!$C$10) -> 0.8 | E15: =IF(C15=0,"Pendiente",IF(C15>=Parametros!$C$10,"Completado","En curso")) -> En curso | F15: =IF(C15=0,"-",_xlfn.MINIFS('CARGAR OPERACIONES'!$B$7:$B$506,'CARGAR OPERACIONES'!$O$7:$O$506,$B15)) -> 46248 | G15: =IF(C15=0,"-",_xlfn.MAXIFS('CARGAR OPERACIONES'!$B$7:$B$506,'CARGAR OPERACIONES'!$O$7:$O$506,$B15)) -> 46304 | H15: =COUNTIFS('CARGAR OPERACIONES'!$O$7:$O$506,$B15,'CARGAR OPERACIONES'!$S$7:$S$506,">0") -> 6 | I15: =COUNTIFS('CARGAR OPERACIONES'!$O$7:$O$506,$B15,'CARGAR OPERACIONES'!$S$7:$S$506,"<=0") -> 10 | J15: =IF(C15=0,"-",H15/C15) -> 0.375 | K15: =IF(C15=0,"-",SUMIFS('CARGAR OPERACIONES'!$S$7:$S$506,'CARGAR OPERACIONES'!$O$7:$O$506,$B15)) -> 163.84 | L15: =IF(C15=0,"-",IF(I15=0,99,SUMIFS('CARGAR OPERACIONES'!$S$7:$S$506,'CARGAR OPERACIONES'!$O$7:$O$506,$B15,'CARGAR OPERACIONES'!$S$7:$S$506,">0")/-SUMIFS('CARGAR OPERACIONES'!$S$7:$S$506,'CARGAR OPERACIONES'!$O$7:$O$506,$B15,'CARGAR OPERACIONES'!$S$7:$S$506,"<=0"))) -> 1.103153 | M15: =IF(C15=0,"-",K15/C15) -> 10.24 | N15: =IF(C15=0,"-",AVERAGEIFS('CARGAR OPERACIONES'!$U$7:$U$506,'CARGAR OPERACIONES'!$O$7:$O$506,$B15)) -> 0.068266667 | O15: =IF(C15=0,"-",_xlfn.MINIFS('CARGAR OPERACIONES'!$AF$7:$AF$506,'CARGAR OPERACIONES'!$O$7:$O$506,$B15)) -> -680.96 | P15: =IF(C15=0,"-",-MIN(0,_xlfn.MINIFS('CARGAR OPERACIONES'!$AG$7:$AG$506,'CARGAR OPERACIONES'!$O$7:$O$506,$B15))) -> 4 | Q15: =IF(C15=0,"-",COUNTIFS('CARGAR OPERACIONES'!$O$7:$O$506,$B15,'CARGAR OPERACIONES'!$L$7:$L$506,"SI")/C15) -> 0.9375 | R15: =IF(C15=0,"-",Parametros!$C$6+SUMIFS('CARGAR OPERACIONES'!$S$7:$S$506,'CARGAR OPERACIONES'!$O$7:$O$506,"<="&$B15)) -> 8748.36 | S15: =IF(C15=0,"",IF(L15>=Parametros!$C$11,"✔","✘")) -> ✘ | T15: =IF(C15=0,"",IF(J15>=Parametros!$C$12,"✔","✘")) -> ✘ | U15: =IF(C15=0,"",IF(Q15>=Parametros!$C$13,"✔","✘")) -> ✘
B16: 2 | C16: =COUNTIFS('CARGAR OPERACIONES'!$O$7:$O$506,$B16) -> 0 | D16: =IF(C16=0,"",C16/Parametros!$C$10) | E16: =IF(C16=0,"Pendiente",IF(C16>=Parametros!$C$10,"Completado","En curso")) -> Pendiente | F16: =IF(C16=0,"-",_xlfn.MINIFS('CARGAR OPERACIONES'!$B$7:$B$506,'CARGAR OPERACIONES'!$O$7:$O$506,$B16)) -> - | G16: =IF(C16=0,"-",_xlfn.MAXIFS('CARGAR OPERACIONES'!$B$7:$B$506,'CARGAR OPERACIONES'!$O$7:$O$506,$B16)) -> - | H16: =COUNTIFS('CARGAR OPERACIONES'!$O$7:$O$506,$B16,'CARGAR OPERACIONES'!$S$7:$S$506,">0") -> 0 | I16: =COUNTIFS('CARGAR OPERACIONES'!$O$7:$O$506,$B16,'CARGAR OPERACIONES'!$S$7:$S$506,"<=0") -> 0 | J16: =IF(C16=0,"-",H16/C16) -> - | K16: =IF(C16=0,"-",SUMIFS('CARGAR OPERACIONES'!$S$7:$S$506,'CARGAR OPERACIONES'!$O$7:$O$506,$B16)) -> - | L16: =IF(C16=0,"-",IF(I16=0,99,SUMIFS('CARGAR OPERACIONES'!$S$7:$S$506,'CARGAR OPERACIONES'!$O$7:$O$506,$B16,'CARGAR OPERACIONES'!$S$7:$S$506,">0")/-SUMIFS('CARGAR OPERACIONES'!$S$7:$S$506,'CARGAR OPERACIONES'!$O$7:$O$506,$B16,'CARGAR OPERACIONES'!$S$7:$S$506,"<=0"))) -> - | M16: =IF(C16=0,"-",K16/C16) -> - | N16: =IF(C16=0,"-",AVERAGEIFS('CARGAR OPERACIONES'!$U$7:$U$506,'CARGAR OPERACIONES'!$O$7:$O$506,$B16)) -> - | O16: =IF(C16=0,"-",_xlfn.MINIFS('CARGAR OPERACIONES'!$AF$7:$AF$506,'CARGAR OPERACIONES'!$O$7:$O$506,$B16)) -> - | P16: =IF(C16=0,"-",-MIN(0,_xlfn.MINIFS('CARGAR OPERACIONES'!$AG$7:$AG$506,'CARGAR OPERACIONES'!$O$7:$O$506,$B16))) -> - | Q16: =IF(C16=0,"-",COUNTIFS('CARGAR OPERACIONES'!$O$7:$O$506,$B16,'CARGAR OPERACIONES'!$L$7:$L$506,"SI")/C16) -> - | R16: =IF(C16=0,"-",Parametros!$C$6+SUMIFS('CARGAR OPERACIONES'!$S$7:$S$506,'CARGAR OPERACIONES'!$O$7:$O$506,"<="&$B16)) -> - | S16: =IF(C16=0,"",IF(L16>=Parametros!$C$11,"✔","✘")) | T16: =IF(C16=0,"",IF(J16>=Parametros!$C$12,"✔","✘")) | U16: =IF(C16=0,"",IF(Q16>=Parametros!$C$13,"✔","✘"))
B17: 3 | C17: =COUNTIFS('CARGAR OPERACIONES'!$O$7:$O$506,$B17) -> 0 | D17: =IF(C17=0,"",C17/Parametros!$C$10) | E17: =IF(C17=0,"Pendiente",IF(C17>=Parametros!$C$10,"Completado","En curso")) -> Pendiente | F17: =IF(C17=0,"-",_xlfn.MINIFS('CARGAR OPERACIONES'!$B$7:$B$506,'CARGAR OPERACIONES'!$O$7:$O$506,$B17)) -> - | G17: =IF(C17=0,"-",_xlfn.MAXIFS('CARGAR OPERACIONES'!$B$7:$B$506,'CARGAR OPERACIONES'!$O$7:$O$506,$B17)) -> - | H17: =COUNTIFS('CARGAR OPERACIONES'!$O$7:$O$506,$B17,'CARGAR OPERACIONES'!$S$7:$S$506,">0") -> 0 | I17: =COUNTIFS('CARGAR OPERACIONES'!$O$7:$O$506,$B17,'CARGAR OPERACIONES'!$S$7:$S$506,"<=0") -> 0 | J17: =IF(C17=0,"-",H17/C17) -> - | K17: =IF(C17=0,"-",SUMIFS('CARGAR OPERACIONES'!$S$7:$S$506,'CARGAR OPERACIONES'!$O$7:$O$506,$B17)) -> - | L17: =IF(C17=0,"-",IF(I17=0,99,SUMIFS('CARGAR OPERACIONES'!$S$7:$S$506,'CARGAR OPERACIONES'!$O$7:$O$506,$B17,'CARGAR OPERACIONES'!$S$7:$S$506,">0")/-SUMIFS('CARGAR OPERACIONES'!$S$7:$S$506,'CARGAR OPERACIONES'!$O$7:$O$506,$B17,'CARGAR OPERACIONES'!$S$7:$S$506,"<=0"))) -> - | M17: =IF(C17=0,"-",K17/C17) -> - | N17: =IF(C17=0,"-",AVERAGEIFS('CARGAR OPERACIONES'!$U$7:$U$506,'CARGAR OPERACIONES'!$O$7:$O$506,$B17)) -> - | O17: =IF(C17=0,"-",_xlfn.MINIFS('CARGAR OPERACIONES'!$AF$7:$AF$506,'CARGAR OPERACIONES'!$O$7:$O$506,$B17)) -> - | P17: =IF(C17=0,"-",-MIN(0,_xlfn.MINIFS('CARGAR OPERACIONES'!$AG$7:$AG$506,'CARGAR OPERACIONES'!$O$7:$O$506,$B17))) -> - | Q17: =IF(C17=0,"-",COUNTIFS('CARGAR OPERACIONES'!$O$7:$O$506,$B17,'CARGAR OPERACIONES'!$L$7:$L$506,"SI")/C17) -> - | R17: =IF(C17=0,"-",Parametros!$C$6+SUMIFS('CARGAR OPERACIONES'!$S$7:$S$506,'CARGAR OPERACIONES'!$O$7:$O$506,"<="&$B17)) -> - | S17: =IF(C17=0,"",IF(L17>=Parametros!$C$11,"✔","✘")) | T17: =IF(C17=0,"",IF(J17>=Parametros!$C$12,"✔","✘")) | U17: =IF(C17=0,"",IF(Q17>=Parametros!$C$13,"✔","✘"))
B18: 4 | C18: =COUNTIFS('CARGAR OPERACIONES'!$O$7:$O$506,$B18) -> 0 | D18: =IF(C18=0,"",C18/Parametros!$C$10) | E18: =IF(C18=0,"Pendiente",IF(C18>=Parametros!$C$10,"Completado","En curso")) -> Pendiente | F18: =IF(C18=0,"-",_xlfn.MINIFS('CARGAR OPERACIONES'!$B$7:$B$506,'CARGAR OPERACIONES'!$O$7:$O$506,$B18)) -> - | G18: =IF(C18=0,"-",_xlfn.MAXIFS('CARGAR OPERACIONES'!$B$7:$B$506,'CARGAR OPERACIONES'!$O$7:$O$506,$B18)) -> - | H18: =COUNTIFS('CARGAR OPERACIONES'!$O$7:$O$506,$B18,'CARGAR OPERACIONES'!$S$7:$S$506,">0") -> 0 | I18: =COUNTIFS('CARGAR OPERACIONES'!$O$7:$O$506,$B18,'CARGAR OPERACIONES'!$S$7:$S$506,"<=0") -> 0 | J18: =IF(C18=0,"-",H18/C18) -> - | K18: =IF(C18=0,"-",SUMIFS('CARGAR OPERACIONES'!$S$7:$S$506,'CARGAR OPERACIONES'!$O$7:$O$506,$B18)) -> - | L18: =IF(C18=0,"-",IF(I18=0,99,SUMIFS('CARGAR OPERACIONES'!$S$7:$S$506,'CARGAR OPERACIONES'!$O$7:$O$506,$B18,'CARGAR OPERACIONES'!$S$7:$S$506,">0")/-SUMIFS('CARGAR OPERACIONES'!$S$7:$S$506,'CARGAR OPERACIONES'!$O$7:$O$506,$B18,'CARGAR OPERACIONES'!$S$7:$S$506,"<=0"))) -> - | M18: =IF(C18=0,"-",K18/C18) -> - | N18: =IF(C18=0,"-",AVERAGEIFS('CARGAR OPERACIONES'!$U$7:$U$506,'CARGAR OPERACIONES'!$O$7:$O$506,$B18)) -> - | O18: =IF(C18=0,"-",_xlfn.MINIFS('CARGAR OPERACIONES'!$AF$7:$AF$506,'CARGAR OPERACIONES'!$O$7:$O$506,$B18)) -> - | P18: =IF(C18=0,"-",-MIN(0,_xlfn.MINIFS('CARGAR OPERACIONES'!$AG$7:$AG$506,'CARGAR OPERACIONES'!$O$7:$O$506,$B18))) -> - | Q18: =IF(C18=0,"-",COUNTIFS('CARGAR OPERACIONES'!$O$7:$O$506,$B18,'CARGAR OPERACIONES'!$L$7:$L$506,"SI")/C18) -> - | R18: =IF(C18=0,"-",Parametros!$C$6+SUMIFS('CARGAR OPERACIONES'!$S$7:$S$506,'CARGAR OPERACIONES'!$O$7:$O$506,"<="&$B18)) -> - | S18: =IF(C18=0,"",IF(L18>=Parametros!$C$11,"✔","✘")) | T18: =IF(C18=0,"",IF(J18>=Parametros!$C$12,"✔","✘")) | U18: =IF(C18=0,"",IF(Q18>=Parametros!$C$13,"✔","✘"))
B19: 5 | C19: =COUNTIFS('CARGAR OPERACIONES'!$O$7:$O$506,$B19) -> 0 | D19: =IF(C19=0,"",C19/Parametros!$C$10) | E19: =IF(C19=0,"Pendiente",IF(C19>=Parametros!$C$10,"Completado","En curso")) -> Pendiente | F19: =IF(C19=0,"-",_xlfn.MINIFS('CARGAR OPERACIONES'!$B$7:$B$506,'CARGAR OPERACIONES'!$O$7:$O$506,$B19)) -> - | G19: =IF(C19=0,"-",_xlfn.MAXIFS('CARGAR OPERACIONES'!$B$7:$B$506,'CARGAR OPERACIONES'!$O$7:$O$506,$B19)) -> - | H19: =COUNTIFS('CARGAR OPERACIONES'!$O$7:$O$506,$B19,'CARGAR OPERACIONES'!$S$7:$S$506,">0") -> 0 | I19: =COUNTIFS('CARGAR OPERACIONES'!$O$7:$O$506,$B19,'CARGAR OPERACIONES'!$S$7:$S$506,"<=0") -> 0 | J19: =IF(C19=0,"-",H19/C19) -> - | K19: =IF(C19=0,"-",SUMIFS('CARGAR OPERACIONES'!$S$7:$S$506,'CARGAR OPERACIONES'!$O$7:$O$506,$B19)) -> - | L19: =IF(C19=0,"-",IF(I19=0,99,SUMIFS('CARGAR OPERACIONES'!$S$7:$S$506,'CARGAR OPERACIONES'!$O$7:$O$506,$B19,'CARGAR OPERACIONES'!$S$7:$S$506,">0")/-SUMIFS('CARGAR OPERACIONES'!$S$7:$S$506,'CARGAR OPERACIONES'!$O$7:$O$506,$B19,'CARGAR OPERACIONES'!$S$7:$S$506,"<=0"))) -> - | M19: =IF(C19=0,"-",K19/C19) -> - | N19: =IF(C19=0,"-",AVERAGEIFS('CARGAR OPERACIONES'!$U$7:$U$506,'CARGAR OPERACIONES'!$O$7:$O$506,$B19)) -> - | O19: =IF(C19=0,"-",_xlfn.MINIFS('CARGAR OPERACIONES'!$AF$7:$AF$506,'CARGAR OPERACIONES'!$O$7:$O$506,$B19)) -> - | P19: =IF(C19=0,"-",-MIN(0,_xlfn.MINIFS('CARGAR OPERACIONES'!$AG$7:$AG$506,'CARGAR OPERACIONES'!$O$7:$O$506,$B19))) -> - | Q19: =IF(C19=0,"-",COUNTIFS('CARGAR OPERACIONES'!$O$7:$O$506,$B19,'CARGAR OPERACIONES'!$L$7:$L$506,"SI")/C19) -> - | R19: =IF(C19=0,"-",Parametros!$C$6+SUMIFS('CARGAR OPERACIONES'!$S$7:$S$506,'CARGAR OPERACIONES'!$O$7:$O$506,"<="&$B19)) -> - | S19: =IF(C19=0,"",IF(L19>=Parametros!$C$11,"✔","✘")) | T19: =IF(C19=0,"",IF(J19>=Parametros!$C$12,"✔","✘")) | U19: =IF(C19=0,"",IF(Q19>=Parametros!$C$13,"✔","✘"))
B20: 6 | C20: =COUNTIFS('CARGAR OPERACIONES'!$O$7:$O$506,$B20) -> 0 | D20: =IF(C20=0,"",C20/Parametros!$C$10) | E20: =IF(C20=0,"Pendiente",IF(C20>=Parametros!$C$10,"Completado","En curso")) -> Pendiente | F20: =IF(C20=0,"-",_xlfn.MINIFS('CARGAR OPERACIONES'!$B$7:$B$506,'CARGAR OPERACIONES'!$O$7:$O$506,$B20)) -> - | G20: =IF(C20=0,"-",_xlfn.MAXIFS('CARGAR OPERACIONES'!$B$7:$B$506,'CARGAR OPERACIONES'!$O$7:$O$506,$B20)) -> - | H20: =COUNTIFS('CARGAR OPERACIONES'!$O$7:$O$506,$B20,'CARGAR OPERACIONES'!$S$7:$S$506,">0") -> 0 | I20: =COUNTIFS('CARGAR OPERACIONES'!$O$7:$O$506,$B20,'CARGAR OPERACIONES'!$S$7:$S$506,"<=0") -> 0 | J20: =IF(C20=0,"-",H20/C20) -> - | K20: =IF(C20=0,"-",SUMIFS('CARGAR OPERACIONES'!$S$7:$S$506,'CARGAR OPERACIONES'!$O$7:$O$506,$B20)) -> - | L20: =IF(C20=0,"-",IF(I20=0,99,SUMIFS('CARGAR OPERACIONES'!$S$7:$S$506,'CARGAR OPERACIONES'!$O$7:$O$506,$B20,'CARGAR OPERACIONES'!$S$7:$S$506,">0")/-SUMIFS('CARGAR OPERACIONES'!$S$7:$S$506,'CARGAR OPERACIONES'!$O$7:$O$506,$B20,'CARGAR OPERACIONES'!$S$7:$S$506,"<=0"))) -> - | M20: =IF(C20=0,"-",K20/C20) -> - | N20: =IF(C20=0,"-",AVERAGEIFS('CARGAR OPERACIONES'!$U$7:$U$506,'CARGAR OPERACIONES'!$O$7:$O$506,$B20)) -> - | O20: =IF(C20=0,"-",_xlfn.MINIFS('CARGAR OPERACIONES'!$AF$7:$AF$506,'CARGAR OPERACIONES'!$O$7:$O$506,$B20)) -> - | P20: =IF(C20=0,"-",-MIN(0,_xlfn.MINIFS('CARGAR OPERACIONES'!$AG$7:$AG$506,'CARGAR OPERACIONES'!$O$7:$O$506,$B20))) -> - | Q20: =IF(C20=0,"-",COUNTIFS('CARGAR OPERACIONES'!$O$7:$O$506,$B20,'CARGAR OPERACIONES'!$L$7:$L$506,"SI")/C20) -> - | R20: =IF(C20=0,"-",Parametros!$C$6+SUMIFS('CARGAR OPERACIONES'!$S$7:$S$506,'CARGAR OPERACIONES'!$O$7:$O$506,"<="&$B20)) -> - | S20: =IF(C20=0,"",IF(L20>=Parametros!$C$11,"✔","✘")) | T20: =IF(C20=0,"",IF(J20>=Parametros!$C$12,"✔","✘")) | U20: =IF(C20=0,"",IF(Q20>=Parametros!$C$13,"✔","✘"))
B21: 7 | C21: =COUNTIFS('CARGAR OPERACIONES'!$O$7:$O$506,$B21) -> 0 | D21: =IF(C21=0,"",C21/Parametros!$C$10) | E21: =IF(C21=0,"Pendiente",IF(C21>=Parametros!$C$10,"Completado","En curso")) -> Pendiente | F21: =IF(C21=0,"-",_xlfn.MINIFS('CARGAR OPERACIONES'!$B$7:$B$506,'CARGAR OPERACIONES'!$O$7:$O$506,$B21)) -> - | G21: =IF(C21=0,"-",_xlfn.MAXIFS('CARGAR OPERACIONES'!$B$7:$B$506,'CARGAR OPERACIONES'!$O$7:$O$506,$B21)) -> - | H21: =COUNTIFS('CARGAR OPERACIONES'!$O$7:$O$506,$B21,'CARGAR OPERACIONES'!$S$7:$S$506,">0") -> 0 | I21: =COUNTIFS('CARGAR OPERACIONES'!$O$7:$O$506,$B21,'CARGAR OPERACIONES'!$S$7:$S$506,"<=0") -> 0 | J21: =IF(C21=0,"-",H21/C21) -> - | K21: =IF(C21=0,"-",SUMIFS('CARGAR OPERACIONES'!$S$7:$S$506,'CARGAR OPERACIONES'!$O$7:$O$506,$B21)) -> - | L21: =IF(C21=0,"-",IF(I21=0,99,SUMIFS('CARGAR OPERACIONES'!$S$7:$S$506,'CARGAR OPERACIONES'!$O$7:$O$506,$B21,'CARGAR OPERACIONES'!$S$7:$S$506,">0")/-SUMIFS('CARGAR OPERACIONES'!$S$7:$S$506,'CARGAR OPERACIONES'!$O$7:$O$506,$B21,'CARGAR OPERACIONES'!$S$7:$S$506,"<=0"))) -> - | M21: =IF(C21=0,"-",K21/C21) -> - | N21: =IF(C21=0,"-",AVERAGEIFS('CARGAR OPERACIONES'!$U$7:$U$506,'CARGAR OPERACIONES'!$O$7:$O$506,$B21)) -> - | O21: =IF(C21=0,"-",_xlfn.MINIFS('CARGAR OPERACIONES'!$AF$7:$AF$506,'CARGAR OPERACIONES'!$O$7:$O$506,$B21)) -> - | P21: =IF(C21=0,"-",-MIN(0,_xlfn.MINIFS('CARGAR OPERACIONES'!$AG$7:$AG$506,'CARGAR OPERACIONES'!$O$7:$O$506,$B21))) -> - | Q21: =IF(C21=0,"-",COUNTIFS('CARGAR OPERACIONES'!$O$7:$O$506,$B21,'CARGAR OPERACIONES'!$L$7:$L$506,"SI")/C21) -> - | R21: =IF(C21=0,"-",Parametros!$C$6+SUMIFS('CARGAR OPERACIONES'!$S$7:$S$506,'CARGAR OPERACIONES'!$O$7:$O$506,"<="&$B21)) -> - | S21: =IF(C21=0,"",IF(L21>=Parametros!$C$11,"✔","✘")) | T21: =IF(C21=0,"",IF(J21>=Parametros!$C$12,"✔","✘")) | U21: =IF(C21=0,"",IF(Q21>=Parametros!$C$13,"✔","✘"))
B22: 8 | C22: =COUNTIFS('CARGAR OPERACIONES'!$O$7:$O$506,$B22) -> 0 | D22: =IF(C22=0,"",C22/Parametros!$C$10) | E22: =IF(C22=0,"Pendiente",IF(C22>=Parametros!$C$10,"Completado","En curso")) -> Pendiente | F22: =IF(C22=0,"-",_xlfn.MINIFS('CARGAR OPERACIONES'!$B$7:$B$506,'CARGAR OPERACIONES'!$O$7:$O$506,$B22)) -> - | G22: =IF(C22=0,"-",_xlfn.MAXIFS('CARGAR OPERACIONES'!$B$7:$B$506,'CARGAR OPERACIONES'!$O$7:$O$506,$B22)) -> - | H22: =COUNTIFS('CARGAR OPERACIONES'!$O$7:$O$506,$B22,'CARGAR OPERACIONES'!$S$7:$S$506,">0") -> 0 | I22: =COUNTIFS('CARGAR OPERACIONES'!$O$7:$O$506,$B22,'CARGAR OPERACIONES'!$S$7:$S$506,"<=0") -> 0 | J22: =IF(C22=0,"-",H22/C22) -> - | K22: =IF(C22=0,"-",SUMIFS('CARGAR OPERACIONES'!$S$7:$S$506,'CARGAR OPERACIONES'!$O$7:$O$506,$B22)) -> - | L22: =IF(C22=0,"-",IF(I22=0,99,SUMIFS('CARGAR OPERACIONES'!$S$7:$S$506,'CARGAR OPERACIONES'!$O$7:$O$506,$B22,'CARGAR OPERACIONES'!$S$7:$S$506,">0")/-SUMIFS('CARGAR OPERACIONES'!$S$7:$S$506,'CARGAR OPERACIONES'!$O$7:$O$506,$B22,'CARGAR OPERACIONES'!$S$7:$S$506,"<=0"))) -> - | M22: =IF(C22=0,"-",K22/C22) -> - | N22: =IF(C22=0,"-",AVERAGEIFS('CARGAR OPERACIONES'!$U$7:$U$506,'CARGAR OPERACIONES'!$O$7:$O$506,$B22)) -> - | O22: =IF(C22=0,"-",_xlfn.MINIFS('CARGAR OPERACIONES'!$AF$7:$AF$506,'CARGAR OPERACIONES'!$O$7:$O$506,$B22)) -> - | P22: =IF(C22=0,"-",-MIN(0,_xlfn.MINIFS('CARGAR OPERACIONES'!$AG$7:$AG$506,'CARGAR OPERACIONES'!$O$7:$O$506,$B22))) -> - | Q22: =IF(C22=0,"-",COUNTIFS('CARGAR OPERACIONES'!$O$7:$O$506,$B22,'CARGAR OPERACIONES'!$L$7:$L$506,"SI")/C22) -> - | R22: =IF(C22=0,"-",Parametros!$C$6+SUMIFS('CARGAR OPERACIONES'!$S$7:$S$506,'CARGAR OPERACIONES'!$O$7:$O$506,"<="&$B22)) -> - | S22: =IF(C22=0,"",IF(L22>=Parametros!$C$11,"✔","✘")) | T22: =IF(C22=0,"",IF(J22>=Parametros!$C$12,"✔","✘")) | U22: =IF(C22=0,"",IF(Q22>=Parametros!$C$13,"✔","✘"))
